<?xml version="1.0" ?>
<!-- URDF of the KUKA iiwa 14 robot generated by robcogen and extended manually -->
<!-- Added interias and other properties by hand.                               -->
<robot name="KUKAiiwa14">

  <link name="iiwaBase">
    
    <visual>
      <origin xyz="0.0 0.0 0.0" rpy="0.0 0.0 0.0" />            
      <geometry>
        <mesh filename="package://robot_properties_iiwa/urdf/mesh/iiwa14_base.stl" scale="0.001 0.001 0.001" />
      </geometry>
    </visual>    

  </link>
  
  <link name="L1">
    
    <inertial>
      <origin xyz="0.00000 0.00000 0.00000"/>
      <mass value="4.00000"/>
      <inertia ixx="0.00095" iyy="0.00133" izz="0.00118" ixy="0.00000" ixz="-0.00000" iyz="-0.00006"/>
    </inertial>

    <visual>
      <origin xyz="0.0 0.0 0.0" rpy="0.0 0.0 0.0"/>
      <geometry>
	<mesh filename="package://robot_properties_iiwa/urdf/mesh/iiwa14_link1.stl" scale="0.001 0.001 0.001" />
      </geometry>
    </visual>
    
  </link>

  <link name="L2">
      
    <inertial>
      <origin xyz="0.20920 -0.00010 0.04730"/>
      <mass value="4.00000"/>
      <inertia ixx="0.00145" iyy="0.00986" izz="0.00951" ixy="-0.00000" ixz="0.00096" iyz="-0.00000"/>
    </inertial>

    <visual>
      <origin xyz="0.0 0.0 0.0" rpy="0.0 0.0 0.0"/>
      <geometry>
	<!--cylinder radius="0.12" length="0.2045"/-->
	<mesh filename="package://robot_properties_iiwa/urdf/mesh/iiwa14_link2.stl" scale="0.001 0.001 0.001" />
      </geometry>
    </visual>
    
  </link>

  <link name="L3">
    
    <inertial>
      <origin xyz="0.20920 0.00010 -0.04730"/>
      <mass value="4.00000"/>
      <inertia ixx="0.00145" iyy="0.00986" izz="0.00951" ixy="-0.00000" ixz="-0.00096" iyz="0.00000"/>
    </inertial>
    
    <visual>
      <origin xyz="0.0 0.0 0.0" rpy="0.0 0.0 0.0"/>
      <geometry>
	<!--cylinder radius="0.12" length="0.2155"/-->
	<mesh filename="package://robot_properties_iiwa/urdf/mesh/iiwa14_link3.stl" scale="0.001 0.001 0.001" />
      </geometry>
    </visual>
    
  </link>

  <link name="L4">
    
    <inertial>
      <origin xyz="-0.01260 -0.00010 0.05450"/>
      <mass value="4.00000"/>
      <inertia ixx="0.00100" iyy="0.00133" izz="0.00118" ixy="0.00000" ixz="-0.00000" iyz="0.00006"/>
    </inertial>

    <visual>
      <origin xyz="0.0 0.0 0.0" rpy="0.0 0.0 0.0"/>
      <geometry>
	<!--cylinder radius="0.1" length="0.1845"/-->
	<mesh filename="package://robot_properties_iiwa/urdf/mesh/iiwa14_link4.stl" scale="0.001 0.001 0.001" />
      </geometry>
    </visual>
    
  </link>

  <link name="L5">
    
    <inertial>
      <origin xyz="-0.01260 -0.00010 0.05450"/>
      <mass value="3.00000"/>
      <inertia ixx="0.00100" iyy="0.00133" izz="0.00118" ixy="0.00000" ixz="-0.00000" iyz="0.00001"/>
    </inertial>

    <visual>
      <origin xyz="0.0 0.0 0.0" rpy="0.0 0.0 0.0"/>
      <geometry>
	<!--cylinder radius="0.08" length="0.2155"/-->
	<mesh filename="package://robot_properties_iiwa/urdf/mesh/iiwa14_link5.stl" scale="0.001 0.001 0.001" />
      </geometry>
    </visual>
    
  </link>

  <link name="L6">
    
    <inertial>
      <origin xyz="-0.05000 0.00400 0.12700"/>
      <mass value="2.00000"/>
      <inertia ixx="0.00354" iyy="0.00416" izz="0.00104" ixy="0.00000" ixz="-0.00000" iyz="-0.00000"/>
    </inertial>

    <visual>
      <!-- Align cylinder axis  with z axis of L5 (move about 0.1 in z of L6) -->
      <origin xyz="0.0 0.0 0.0" rpy="0.0 0.0 0.0"/>
      <geometry>
	<!--cylinder radius="0.06" length="0.081"/-->
	<mesh filename="package://robot_properties_iiwa/urdf/mesh/iiwa14_link6.stl" scale="0.001 0.001 0.001" />
      </geometry>
    </visual>
    
  </link>

  <link name="L7">
    
    <inertial>
      <origin xyz="-0.05000 0.00400 0.12700"/>
      <mass value="1.00000"/>
      <inertia ixx="0.00354" iyy="0.00416" izz="0.00104" ixy="0.00000" ixz="0.00000" iyz="-0.00000"/>
    </inertial>

    <visual>      
      <origin xyz="0.0 0.0 0.0" rpy="0.0 0.0 0.0"/>
      <geometry>
	<!--cylinder radius="0.03" length="0.0451"/-->
	<mesh filename="package://robot_properties_iiwa/urdf/mesh/iiwa14_link7.stl" scale="0.001 0.001 0.001" />
      </geometry>
    </visual>
    
  </link>

  <joint name="A1" type="revolute">
    
    <origin xyz="0.00000 0.00000 0.15750" rpy="0.0 0.0 0.0"/>
    <parent link="iiwaBase"/>
    <child  link="L1"/>
    <limit effort="30" velocity="1.0"/>
    <axis xyz="0 0 1"/>
    
  </joint>
  
  <joint name="A2" type="revolute">
    
    <origin xyz="0.00000 0.00000 0.20250" rpy="2.3561944901923457 -1.5707962635746238 2.3561944901923457"/>
    <parent link="L1"/>
    <child  link="L2"/>
    <limit effort="30" velocity="1.0"/>
    <axis xyz="0 0 1"/>
    
  </joint>
  
  <joint name="A3" type="revolute">
    
    <origin xyz="0.20450 0.00000 0.00000" rpy="1.5707963267948948 -4.371139000186238E-8 1.5707963705062866"/>
    <parent link="L2"/>
    <child  link="L3"/>
    <limit effort="30" velocity="1.0"/>
    <axis xyz="0 0 1"/>
    
  </joint>
  
  <joint name="A4" type="revolute">
    
    <origin xyz="0.00000 0.00000 0.21550" rpy="1.5707963705062866 -0.0 0.0"/>
    <parent link="L3"/>
    <child  link="L4"/>
    <limit effort="30" velocity="1.0"/>
    <axis xyz="0 0 1"/>
    
  </joint>
  
  <joint name="A5" type="revolute">
    
    <origin xyz="0.00000 0.18450 0.00000" rpy="-1.5707963705062866 0.0 -0.0"/>
    <parent link="L4"/>
    <child  link="L5"/>
    <limit effort="30" velocity="1.0"/>
    <axis xyz="0 0 1"/>
    
  </joint>
  
  <joint name="A6" type="revolute">
    
    <origin xyz="0.00000 -0.06070 0.21550" rpy="2.3561944901923457 -1.5707962635746238 2.3561944901923457"/>
    <parent link="L5"/>
    <child  link="L6"/>
    <limit effort="30" velocity="1.0"/>
    <axis xyz="0 0 1"/>
    
  </joint>
  
  <joint name="A7" type="revolute">
    
    <origin xyz="0.08100 0.00000 0.06070" rpy="1.5707963267948948 -4.371139000186238E-8 1.5707963705062866"/>
    <parent link="L6"/>
    <child  link="L7"/>
    <limit effort="30" velocity="1.0"/>
    <axis xyz="0 0 1"/>
    
  </joint>
</robot>
